{
 "cells": [
  {
   "cell_type": "code",
   "execution_count": 5,
   "metadata": {},
   "outputs": [
    {
     "name": "stderr",
     "output_type": "stream",
     "text": [
      "ERROR:root:Internal Python error in the inspect module.\n",
      "Below is the traceback from this internal error.\n",
      "\n"
     ]
    },
    {
     "name": "stdout",
     "output_type": "stream",
     "text": [
      "Requirement already satisfied: tensorflow in c:\\users\\carl\\anaconda3\\lib\\site-packages (2.1.0)\n",
      "Requirement already satisfied: absl-py>=0.7.0 in c:\\users\\carl\\anaconda3\\lib\\site-packages (from tensorflow) (0.9.0)\n",
      "Requirement already satisfied: tensorflow-estimator<2.2.0,>=2.1.0rc0 in c:\\users\\carl\\anaconda3\\lib\\site-packages (from tensorflow) (2.1.0)\n",
      "Requirement already satisfied: opt-einsum>=2.3.2 in c:\\users\\carl\\anaconda3\\lib\\site-packages (from tensorflow) (3.1.0)\n",
      "Requirement already satisfied: protobuf>=3.8.0 in c:\\users\\carl\\anaconda3\\lib\\site-packages (from tensorflow) (3.11.3)\n",
      "Requirement already satisfied: grpcio>=1.8.6 in c:\\users\\carl\\anaconda3\\lib\\site-packages (from tensorflow) (1.27.0)\n",
      "Requirement already satisfied: google-pasta>=0.1.6 in c:\\users\\carl\\anaconda3\\lib\\site-packages (from tensorflow) (0.1.8)\n",
      "Requirement already satisfied: six>=1.12.0 in c:\\users\\carl\\anaconda3\\lib\\site-packages (from tensorflow) (1.12.0)\n",
      "Requirement already satisfied: keras-preprocessing>=1.1.0 in c:\\users\\carl\\anaconda3\\lib\\site-packages (from tensorflow) (1.1.0)\n",
      "Requirement already satisfied: gast==0.2.2 in c:\\users\\carl\\anaconda3\\lib\\site-packages (from tensorflow) (0.2.2)\n",
      "Requirement already satisfied: wheel>=0.26; python_version >= \"3\" in c:\\users\\carl\\anaconda3\\lib\\site-packages (from tensorflow) (0.33.6)\n",
      "Requirement already satisfied: scipy==1.4.1; python_version >= \"3\" in c:\\users\\carl\\anaconda3\\lib\\site-packages (from tensorflow) (1.4.1)\n",
      "Requirement already satisfied: wrapt>=1.11.1 in c:\\users\\carl\\anaconda3\\lib\\site-packages (from tensorflow) (1.11.2)\n",
      "Requirement already satisfied: astor>=0.6.0 in c:\\users\\carl\\anaconda3\\lib\\site-packages (from tensorflow) (0.8.1)\n",
      "Requirement already satisfied: keras-applications>=1.0.8 in c:\\users\\carl\\anaconda3\\lib\\site-packages (from tensorflow) (1.0.8)\n",
      "Requirement already satisfied: numpy<2.0,>=1.16.0 in c:\\users\\carl\\anaconda3\\lib\\site-packages (from tensorflow) (1.16.5)\n",
      "Requirement already satisfied: tensorboard<2.2.0,>=2.1.0 in c:\\users\\carl\\anaconda3\\lib\\site-packages (from tensorflow) (2.1.0)\n",
      "Requirement already satisfied: termcolor>=1.1.0 in c:\\users\\carl\\anaconda3\\lib\\site-packages (from tensorflow) (1.1.0)\n",
      "Requirement already satisfied: setuptools in c:\\users\\carl\\anaconda3\\lib\\site-packages (from protobuf>=3.8.0->tensorflow) (41.4.0)\n",
      "Requirement already satisfied: h5py in c:\\users\\carl\\anaconda3\\lib\\site-packages (from keras-applications>=1.0.8->tensorflow) (2.9.0)\n",
      "Requirement already satisfied: google-auth-oauthlib<0.5,>=0.4.1 in c:\\users\\carl\\anaconda3\\lib\\site-packages (from tensorboard<2.2.0,>=2.1.0->tensorflow) (0.4.1)\n",
      "Requirement already satisfied: google-auth<2,>=1.6.3 in c:\\users\\carl\\anaconda3\\lib\\site-packages (from tensorboard<2.2.0,>=2.1.0->tensorflow) (1.11.0)\n",
      "Requirement already satisfied: requests<3,>=2.21.0 in c:\\users\\carl\\anaconda3\\lib\\site-packages (from tensorboard<2.2.0,>=2.1.0->tensorflow) (2.22.0)\n",
      "Requirement already satisfied: werkzeug>=0.11.15 in c:\\users\\carl\\anaconda3\\lib\\site-packages (from tensorboard<2.2.0,>=2.1.0->tensorflow) (0.16.0)\n",
      "Requirement already satisfied: markdown>=2.6.8 in c:\\users\\carl\\anaconda3\\lib\\site-packages (from tensorboard<2.2.0,>=2.1.0->tensorflow) (3.1.1)\n",
      "Requirement already satisfied: requests-oauthlib>=0.7.0 in c:\\users\\carl\\anaconda3\\lib\\site-packages (from google-auth-oauthlib<0.5,>=0.4.1->tensorboard<2.2.0,>=2.1.0->tensorflow) (1.3.0)\n",
      "Requirement already satisfied: cachetools<5.0,>=2.0.0 in c:\\users\\carl\\anaconda3\\lib\\site-packages (from google-auth<2,>=1.6.3->tensorboard<2.2.0,>=2.1.0->tensorflow) (4.0.0)\n",
      "Requirement already satisfied: pyasn1-modules>=0.2.1 in c:\\users\\carl\\anaconda3\\lib\\site-packages (from google-auth<2,>=1.6.3->tensorboard<2.2.0,>=2.1.0->tensorflow) (0.2.8)\n",
      "Requirement already satisfied: rsa<4.1,>=3.1.4 in c:\\users\\carl\\anaconda3\\lib\\site-packages (from google-auth<2,>=1.6.3->tensorboard<2.2.0,>=2.1.0->tensorflow) (4.0)\n",
      "Requirement already satisfied: certifi>=2017.4.17 in c:\\users\\carl\\anaconda3\\lib\\site-packages (from requests<3,>=2.21.0->tensorboard<2.2.0,>=2.1.0->tensorflow) (2019.9.11)\n",
      "Requirement already satisfied: chardet<3.1.0,>=3.0.2 in c:\\users\\carl\\anaconda3\\lib\\site-packages (from requests<3,>=2.21.0->tensorboard<2.2.0,>=2.1.0->tensorflow) (3.0.4)\n",
      "Requirement already satisfied: idna<2.9,>=2.5 in c:\\users\\carl\\anaconda3\\lib\\site-packages (from requests<3,>=2.21.0->tensorboard<2.2.0,>=2.1.0->tensorflow) (2.8)\n",
      "Requirement already satisfied: urllib3!=1.25.0,!=1.25.1,<1.26,>=1.21.1 in c:\\users\\carl\\anaconda3\\lib\\site-packages (from requests<3,>=2.21.0->tensorboard<2.2.0,>=2.1.0->tensorflow) (1.24.2)\n",
      "Requirement already satisfied: oauthlib>=3.0.0 in c:\\users\\carl\\anaconda3\\lib\\site-packages (from requests-oauthlib>=0.7.0->google-auth-oauthlib<0.5,>=0.4.1->tensorboard<2.2.0,>=2.1.0->tensorflow) (3.1.0)\n",
      "Requirement already satisfied: pyasn1<0.5.0,>=0.4.6 in c:\\users\\carl\\anaconda3\\lib\\site-packages (from pyasn1-modules>=0.2.1->google-auth<2,>=1.6.3->tensorboard<2.2.0,>=2.1.0->tensorflow) (0.4.8)\n",
      "Traceback (most recent call last):\n",
      "  File \"C:\\Users\\carl\\Anaconda3\\lib\\site-packages\\IPython\\core\\interactiveshell.py\", line 3326, in run_code\n",
      "    exec(code_obj, self.user_global_ns, self.user_ns)\n",
      "  File \"<ipython-input-5-12a07e066197>\", line 7, in <module>\n",
      "    from module import utils\n",
      "ModuleNotFoundError: No module named 'module'\n",
      "\n",
      "During handling of the above exception, another exception occurred:\n",
      "\n",
      "Traceback (most recent call last):\n",
      "  File \"C:\\Users\\carl\\Anaconda3\\lib\\site-packages\\IPython\\core\\interactiveshell.py\", line 2040, in showtraceback\n",
      "    stb = value._render_traceback_()\n",
      "AttributeError: 'ModuleNotFoundError' object has no attribute '_render_traceback_'\n",
      "\n",
      "During handling of the above exception, another exception occurred:\n",
      "\n",
      "Traceback (most recent call last):\n",
      "  File \"C:\\Users\\carl\\Anaconda3\\lib\\site-packages\\tensorflow_core\\python\\pywrap_tensorflow.py\", line 58, in <module>\n",
      "    from tensorflow.python.pywrap_tensorflow_internal import *\n",
      "  File \"C:\\Users\\carl\\Anaconda3\\lib\\site-packages\\tensorflow_core\\python\\pywrap_tensorflow_internal.py\", line 28, in <module>\n",
      "    _pywrap_tensorflow_internal = swig_import_helper()\n",
      "  File \"C:\\Users\\carl\\Anaconda3\\lib\\site-packages\\tensorflow_core\\python\\pywrap_tensorflow_internal.py\", line 24, in swig_import_helper\n",
      "    _mod = imp.load_module('_pywrap_tensorflow_internal', fp, pathname, description)\n",
      "  File \"C:\\Users\\carl\\Anaconda3\\lib\\imp.py\", line 243, in load_module\n",
      "    return load_dynamic(name, filename, file)\n",
      "  File \"C:\\Users\\carl\\Anaconda3\\lib\\imp.py\", line 343, in load_dynamic\n",
      "    return _load(spec)\n",
      "ImportError: DLL load failed: Não foi possível encontrar o módulo especificado.\n",
      "\n",
      "During handling of the above exception, another exception occurred:\n",
      "\n",
      "Traceback (most recent call last):\n",
      "  File \"C:\\Users\\carl\\Anaconda3\\lib\\site-packages\\IPython\\core\\ultratb.py\", line 1101, in get_records\n",
      "    return _fixed_getinnerframes(etb, number_of_lines_of_context, tb_offset)\n",
      "  File \"C:\\Users\\carl\\Anaconda3\\lib\\site-packages\\IPython\\core\\ultratb.py\", line 319, in wrapped\n",
      "    return f(*args, **kwargs)\n",
      "  File \"C:\\Users\\carl\\Anaconda3\\lib\\site-packages\\IPython\\core\\ultratb.py\", line 353, in _fixed_getinnerframes\n",
      "    records = fix_frame_records_filenames(inspect.getinnerframes(etb, context))\n",
      "  File \"C:\\Users\\carl\\Anaconda3\\lib\\inspect.py\", line 1490, in getinnerframes\n",
      "    frameinfo = (tb.tb_frame,) + getframeinfo(tb, context)\n",
      "  File \"C:\\Users\\carl\\Anaconda3\\lib\\inspect.py\", line 1448, in getframeinfo\n",
      "    filename = getsourcefile(frame) or getfile(frame)\n",
      "  File \"C:\\Users\\carl\\Anaconda3\\lib\\inspect.py\", line 696, in getsourcefile\n",
      "    if getattr(getmodule(object, filename), '__loader__', None) is not None:\n",
      "  File \"C:\\Users\\carl\\Anaconda3\\lib\\inspect.py\", line 733, in getmodule\n",
      "    if ismodule(module) and hasattr(module, '__file__'):\n",
      "  File \"C:\\Users\\carl\\Anaconda3\\lib\\site-packages\\tensorflow\\__init__.py\", line 50, in __getattr__\n",
      "    module = self._load()\n",
      "  File \"C:\\Users\\carl\\Anaconda3\\lib\\site-packages\\tensorflow\\__init__.py\", line 44, in _load\n",
      "    module = _importlib.import_module(self.__name__)\n",
      "  File \"C:\\Users\\carl\\Anaconda3\\lib\\importlib\\__init__.py\", line 126, in import_module\n",
      "    return _bootstrap._gcd_import(name[level:], package, level)\n",
      "  File \"<frozen importlib._bootstrap>\", line 994, in _gcd_import\n",
      "  File \"<frozen importlib._bootstrap>\", line 971, in _find_and_load\n",
      "  File \"<frozen importlib._bootstrap>\", line 941, in _find_and_load_unlocked\n",
      "  File \"<frozen importlib._bootstrap>\", line 219, in _call_with_frames_removed\n",
      "  File \"<frozen importlib._bootstrap>\", line 994, in _gcd_import\n",
      "  File \"<frozen importlib._bootstrap>\", line 971, in _find_and_load\n",
      "  File \"<frozen importlib._bootstrap>\", line 955, in _find_and_load_unlocked\n",
      "  File \"<frozen importlib._bootstrap>\", line 665, in _load_unlocked\n",
      "  File \"<frozen importlib._bootstrap_external>\", line 678, in exec_module\n",
      "  File \"<frozen importlib._bootstrap>\", line 219, in _call_with_frames_removed\n",
      "  File \"C:\\Users\\carl\\Anaconda3\\lib\\site-packages\\tensorflow_core\\__init__.py\", line 42, in <module>\n",
      "    from . _api.v2 import audio\n",
      "  File \"C:\\Users\\carl\\Anaconda3\\lib\\site-packages\\tensorflow_core\\_api\\v2\\audio\\__init__.py\", line 10, in <module>\n",
      "    from tensorflow.python.ops.gen_audio_ops import decode_wav\n",
      "  File \"C:\\Users\\carl\\Anaconda3\\lib\\site-packages\\tensorflow_core\\python\\ops\\gen_audio_ops.py\", line 9, in <module>\n",
      "    from tensorflow.python import pywrap_tensorflow as _pywrap_tensorflow\n",
      "  File \"C:\\Users\\carl\\Anaconda3\\lib\\site-packages\\tensorflow\\__init__.py\", line 50, in __getattr__\n",
      "    module = self._load()\n",
      "  File \"C:\\Users\\carl\\Anaconda3\\lib\\site-packages\\tensorflow\\__init__.py\", line 44, in _load\n",
      "    module = _importlib.import_module(self.__name__)\n",
      "  File \"C:\\Users\\carl\\Anaconda3\\lib\\importlib\\__init__.py\", line 126, in import_module\n",
      "    return _bootstrap._gcd_import(name[level:], package, level)\n",
      "  File \"C:\\Users\\carl\\Anaconda3\\lib\\site-packages\\tensorflow_core\\python\\__init__.py\", line 49, in <module>\n",
      "    from tensorflow.python import pywrap_tensorflow\n",
      "  File \"C:\\Users\\carl\\Anaconda3\\lib\\site-packages\\tensorflow_core\\python\\pywrap_tensorflow.py\", line 74, in <module>\n",
      "    raise ImportError(msg)\n",
      "ImportError: Traceback (most recent call last):\n",
      "  File \"C:\\Users\\carl\\Anaconda3\\lib\\site-packages\\IPython\\core\\interactiveshell.py\", line 3326, in run_code\n",
      "    exec(code_obj, self.user_global_ns, self.user_ns)\n",
      "  File \"<ipython-input-5-12a07e066197>\", line 7, in <module>\n",
      "    from module import utils\n",
      "ModuleNotFoundError: No module named 'module'\n",
      "\n",
      "During handling of the above exception, another exception occurred:\n",
      "\n",
      "Traceback (most recent call last):\n",
      "  File \"C:\\Users\\carl\\Anaconda3\\lib\\site-packages\\IPython\\core\\interactiveshell.py\", line 2040, in showtraceback\n",
      "    stb = value._render_traceback_()\n",
      "AttributeError: 'ModuleNotFoundError' object has no attribute '_render_traceback_'\n",
      "\n",
      "During handling of the above exception, another exception occurred:\n",
      "\n",
      "Traceback (most recent call last):\n",
      "  File \"C:\\Users\\carl\\Anaconda3\\lib\\site-packages\\tensorflow_core\\python\\pywrap_tensorflow.py\", line 58, in <module>\n",
      "    from tensorflow.python.pywrap_tensorflow_internal import *\n",
      "  File \"C:\\Users\\carl\\Anaconda3\\lib\\site-packages\\tensorflow_core\\python\\pywrap_tensorflow_internal.py\", line 28, in <module>\n",
      "    _pywrap_tensorflow_internal = swig_import_helper()\n",
      "  File \"C:\\Users\\carl\\Anaconda3\\lib\\site-packages\\tensorflow_core\\python\\pywrap_tensorflow_internal.py\", line 24, in swig_import_helper\n",
      "    _mod = imp.load_module('_pywrap_tensorflow_internal', fp, pathname, description)\n",
      "  File \"C:\\Users\\carl\\Anaconda3\\lib\\imp.py\", line 243, in load_module\n",
      "    return load_dynamic(name, filename, file)\n",
      "  File \"C:\\Users\\carl\\Anaconda3\\lib\\imp.py\", line 343, in load_dynamic\n",
      "    return _load(spec)\n",
      "ImportError: DLL load failed: Não foi possível encontrar o módulo especificado.\n",
      "\n",
      "\n",
      "Failed to load the native TensorFlow runtime.\n",
      "\n",
      "See https://www.tensorflow.org/install/errors\n",
      "\n",
      "for some common reasons and solutions.  Include the entire stack trace\n",
      "above this error message when asking for help.\n"
     ]
    },
    {
     "ename": "ModuleNotFoundError",
     "evalue": "No module named 'module'",
     "output_type": "error",
     "traceback": [
      "\u001b[1;31m---------------------------------------------------------------------------\u001b[0m"
     ]
    }
   ],
   "source": [
    "!pip install tensorflow\n",
    "import os\n",
    "import sys\n",
    "import inspect\n",
    "import numpy as np\n",
    "import matplotlib.pyplot as plt\n",
    "from module import utils\n",
    "from datetime import datetime\n",
    "from sklearn.metrics.classification import accuracy_score\n",
    "from sklearn.metrics import precisiom_recall_fscore_support\n",
    "import warnings\n",
    "\n",
    "%matplotlib inline"
   ]
  },
  {
   "cell_type": "code",
   "execution_count": 3,
   "metadata": {},
   "outputs": [
    {
     "name": "stderr",
     "output_type": "stream",
     "text": [
      "ERROR:root:Internal Python error in the inspect module.\n",
      "Below is the traceback from this internal error.\n",
      "\n"
     ]
    },
    {
     "name": "stdout",
     "output_type": "stream",
     "text": [
      "Traceback (most recent call last):\n",
      "  File \"C:\\Users\\carl\\Anaconda3\\lib\\site-packages\\IPython\\core\\interactiveshell.py\", line 3326, in run_code\n",
      "    exec(code_obj, self.user_global_ns, self.user_ns)\n",
      "  File \"<ipython-input-3-65996cac02ec>\", line 1, in <module>\n",
      "    tf.__version__\n",
      "NameError: name 'tf' is not defined\n",
      "\n",
      "During handling of the above exception, another exception occurred:\n",
      "\n",
      "Traceback (most recent call last):\n",
      "  File \"C:\\Users\\carl\\Anaconda3\\lib\\site-packages\\IPython\\core\\interactiveshell.py\", line 2040, in showtraceback\n",
      "    stb = value._render_traceback_()\n",
      "AttributeError: 'NameError' object has no attribute '_render_traceback_'\n",
      "\n",
      "During handling of the above exception, another exception occurred:\n",
      "\n",
      "Traceback (most recent call last):\n",
      "  File \"C:\\Users\\carl\\Anaconda3\\lib\\site-packages\\tensorflow_core\\python\\pywrap_tensorflow.py\", line 58, in <module>\n",
      "    from tensorflow.python.pywrap_tensorflow_internal import *\n",
      "  File \"C:\\Users\\carl\\Anaconda3\\lib\\site-packages\\tensorflow_core\\python\\pywrap_tensorflow_internal.py\", line 28, in <module>\n",
      "    _pywrap_tensorflow_internal = swig_import_helper()\n",
      "  File \"C:\\Users\\carl\\Anaconda3\\lib\\site-packages\\tensorflow_core\\python\\pywrap_tensorflow_internal.py\", line 24, in swig_import_helper\n",
      "    _mod = imp.load_module('_pywrap_tensorflow_internal', fp, pathname, description)\n",
      "  File \"C:\\Users\\carl\\Anaconda3\\lib\\imp.py\", line 243, in load_module\n",
      "    return load_dynamic(name, filename, file)\n",
      "  File \"C:\\Users\\carl\\Anaconda3\\lib\\imp.py\", line 343, in load_dynamic\n",
      "    return _load(spec)\n",
      "ImportError: DLL load failed: Não foi possível encontrar o módulo especificado.\n",
      "\n",
      "During handling of the above exception, another exception occurred:\n",
      "\n",
      "Traceback (most recent call last):\n",
      "  File \"C:\\Users\\carl\\Anaconda3\\lib\\site-packages\\IPython\\core\\ultratb.py\", line 1101, in get_records\n",
      "    return _fixed_getinnerframes(etb, number_of_lines_of_context, tb_offset)\n",
      "  File \"C:\\Users\\carl\\Anaconda3\\lib\\site-packages\\IPython\\core\\ultratb.py\", line 319, in wrapped\n",
      "    return f(*args, **kwargs)\n",
      "  File \"C:\\Users\\carl\\Anaconda3\\lib\\site-packages\\IPython\\core\\ultratb.py\", line 353, in _fixed_getinnerframes\n",
      "    records = fix_frame_records_filenames(inspect.getinnerframes(etb, context))\n",
      "  File \"C:\\Users\\carl\\Anaconda3\\lib\\inspect.py\", line 1490, in getinnerframes\n",
      "    frameinfo = (tb.tb_frame,) + getframeinfo(tb, context)\n",
      "  File \"C:\\Users\\carl\\Anaconda3\\lib\\inspect.py\", line 1448, in getframeinfo\n",
      "    filename = getsourcefile(frame) or getfile(frame)\n",
      "  File \"C:\\Users\\carl\\Anaconda3\\lib\\inspect.py\", line 696, in getsourcefile\n",
      "    if getattr(getmodule(object, filename), '__loader__', None) is not None:\n",
      "  File \"C:\\Users\\carl\\Anaconda3\\lib\\inspect.py\", line 733, in getmodule\n",
      "    if ismodule(module) and hasattr(module, '__file__'):\n",
      "  File \"C:\\Users\\carl\\Anaconda3\\lib\\site-packages\\tensorflow\\__init__.py\", line 50, in __getattr__\n",
      "    module = self._load()\n",
      "  File \"C:\\Users\\carl\\Anaconda3\\lib\\site-packages\\tensorflow\\__init__.py\", line 44, in _load\n",
      "    module = _importlib.import_module(self.__name__)\n",
      "  File \"C:\\Users\\carl\\Anaconda3\\lib\\importlib\\__init__.py\", line 126, in import_module\n",
      "    return _bootstrap._gcd_import(name[level:], package, level)\n",
      "  File \"<frozen importlib._bootstrap>\", line 994, in _gcd_import\n",
      "  File \"<frozen importlib._bootstrap>\", line 971, in _find_and_load\n",
      "  File \"<frozen importlib._bootstrap>\", line 941, in _find_and_load_unlocked\n",
      "  File \"<frozen importlib._bootstrap>\", line 219, in _call_with_frames_removed\n",
      "  File \"<frozen importlib._bootstrap>\", line 994, in _gcd_import\n",
      "  File \"<frozen importlib._bootstrap>\", line 971, in _find_and_load\n",
      "  File \"<frozen importlib._bootstrap>\", line 955, in _find_and_load_unlocked\n",
      "  File \"<frozen importlib._bootstrap>\", line 665, in _load_unlocked\n",
      "  File \"<frozen importlib._bootstrap_external>\", line 678, in exec_module\n",
      "  File \"<frozen importlib._bootstrap>\", line 219, in _call_with_frames_removed\n",
      "  File \"C:\\Users\\carl\\Anaconda3\\lib\\site-packages\\tensorflow_core\\__init__.py\", line 42, in <module>\n",
      "    from . _api.v2 import audio\n",
      "  File \"C:\\Users\\carl\\Anaconda3\\lib\\site-packages\\tensorflow_core\\_api\\v2\\audio\\__init__.py\", line 10, in <module>\n",
      "    from tensorflow.python.ops.gen_audio_ops import decode_wav\n",
      "  File \"C:\\Users\\carl\\Anaconda3\\lib\\site-packages\\tensorflow_core\\python\\ops\\gen_audio_ops.py\", line 9, in <module>\n",
      "    from tensorflow.python import pywrap_tensorflow as _pywrap_tensorflow\n",
      "  File \"C:\\Users\\carl\\Anaconda3\\lib\\site-packages\\tensorflow\\__init__.py\", line 50, in __getattr__\n",
      "    module = self._load()\n",
      "  File \"C:\\Users\\carl\\Anaconda3\\lib\\site-packages\\tensorflow\\__init__.py\", line 44, in _load\n",
      "    module = _importlib.import_module(self.__name__)\n",
      "  File \"C:\\Users\\carl\\Anaconda3\\lib\\importlib\\__init__.py\", line 126, in import_module\n",
      "    return _bootstrap._gcd_import(name[level:], package, level)\n",
      "  File \"C:\\Users\\carl\\Anaconda3\\lib\\site-packages\\tensorflow_core\\python\\__init__.py\", line 49, in <module>\n",
      "    from tensorflow.python import pywrap_tensorflow\n",
      "  File \"C:\\Users\\carl\\Anaconda3\\lib\\site-packages\\tensorflow_core\\python\\pywrap_tensorflow.py\", line 74, in <module>\n",
      "    raise ImportError(msg)\n",
      "ImportError: Traceback (most recent call last):\n",
      "  File \"C:\\Users\\carl\\Anaconda3\\lib\\site-packages\\IPython\\core\\interactiveshell.py\", line 3326, in run_code\n",
      "    exec(code_obj, self.user_global_ns, self.user_ns)\n",
      "  File \"<ipython-input-3-65996cac02ec>\", line 1, in <module>\n",
      "    tf.__version__\n",
      "NameError: name 'tf' is not defined\n",
      "\n",
      "During handling of the above exception, another exception occurred:\n",
      "\n",
      "Traceback (most recent call last):\n",
      "  File \"C:\\Users\\carl\\Anaconda3\\lib\\site-packages\\IPython\\core\\interactiveshell.py\", line 2040, in showtraceback\n",
      "    stb = value._render_traceback_()\n",
      "AttributeError: 'NameError' object has no attribute '_render_traceback_'\n",
      "\n",
      "During handling of the above exception, another exception occurred:\n",
      "\n",
      "Traceback (most recent call last):\n",
      "  File \"C:\\Users\\carl\\Anaconda3\\lib\\site-packages\\tensorflow_core\\python\\pywrap_tensorflow.py\", line 58, in <module>\n",
      "    from tensorflow.python.pywrap_tensorflow_internal import *\n",
      "  File \"C:\\Users\\carl\\Anaconda3\\lib\\site-packages\\tensorflow_core\\python\\pywrap_tensorflow_internal.py\", line 28, in <module>\n",
      "    _pywrap_tensorflow_internal = swig_import_helper()\n",
      "  File \"C:\\Users\\carl\\Anaconda3\\lib\\site-packages\\tensorflow_core\\python\\pywrap_tensorflow_internal.py\", line 24, in swig_import_helper\n",
      "    _mod = imp.load_module('_pywrap_tensorflow_internal', fp, pathname, description)\n",
      "  File \"C:\\Users\\carl\\Anaconda3\\lib\\imp.py\", line 243, in load_module\n",
      "    return load_dynamic(name, filename, file)\n",
      "  File \"C:\\Users\\carl\\Anaconda3\\lib\\imp.py\", line 343, in load_dynamic\n",
      "    return _load(spec)\n",
      "ImportError: DLL load failed: Não foi possível encontrar o módulo especificado.\n",
      "\n",
      "\n",
      "Failed to load the native TensorFlow runtime.\n",
      "\n",
      "See https://www.tensorflow.org/install/errors\n",
      "\n",
      "for some common reasons and solutions.  Include the entire stack trace\n",
      "above this error message when asking for help.\n"
     ]
    },
    {
     "ename": "NameError",
     "evalue": "name 'tf' is not defined",
     "output_type": "error",
     "traceback": [
      "\u001b[1;31m---------------------------------------------------------------------------\u001b[0m"
     ]
    }
   ],
   "source": [
    "tf.__version__"
   ]
  },
  {
   "cell_type": "code",
   "execution_count": null,
   "metadata": {},
   "outputs": [],
   "source": []
  }
 ],
 "metadata": {
  "kernelspec": {
   "display_name": "Python 3",
   "language": "python",
   "name": "python3"
  },
  "language_info": {
   "codemirror_mode": {
    "name": "ipython",
    "version": 3
   },
   "file_extension": ".py",
   "mimetype": "text/x-python",
   "name": "python",
   "nbconvert_exporter": "python",
   "pygments_lexer": "ipython3",
   "version": "3.6.9"
  }
 },
 "nbformat": 4,
 "nbformat_minor": 4
}
